[2025-03-20T11:45:51.417+0000] {local_task_job_runner.py:123} INFO - ::group::Pre task execution logs
[2025-03-20T11:45:51.457+0000] {taskinstance.py:2614} INFO - Dependencies all met for dep_context=non-requeueable deps ti=<TaskInstance: ETL_breweries_list.clean_data manual__2025-03-20T11:43:53.685238+00:00 [queued]>
[2025-03-20T11:45:51.477+0000] {taskinstance.py:2614} INFO - Dependencies all met for dep_context=requeueable deps ti=<TaskInstance: ETL_breweries_list.clean_data manual__2025-03-20T11:43:53.685238+00:00 [queued]>
[2025-03-20T11:45:51.478+0000] {taskinstance.py:2867} INFO - Starting attempt 1 of 1
[2025-03-20T11:45:51.501+0000] {taskinstance.py:2890} INFO - Executing <Task(SparkSubmitOperator): clean_data> on 2025-03-20 11:43:53.685238+00:00
[2025-03-20T11:45:51.513+0000] {warnings.py:112} WARNING - /home/***/.local/lib/python3.12/site-packages/***/task/task_runner/standard_task_runner.py:70: DeprecationWarning: This process (pid=332) is multi-threaded, use of fork() may lead to deadlocks in the child.
  pid = os.fork()

[2025-03-20T11:45:51.519+0000] {standard_task_runner.py:72} INFO - Started process 341 to run task
[2025-03-20T11:45:51.519+0000] {standard_task_runner.py:104} INFO - Running: ['***', 'tasks', 'run', 'ETL_breweries_list', 'clean_data', 'manual__2025-03-20T11:43:53.685238+00:00', '--job-id', '133', '--raw', '--subdir', 'DAGS_FOLDER/breweries_list_etl.py', '--cfg-path', '/tmp/tmpglnsdv3s']
[2025-03-20T11:45:51.520+0000] {standard_task_runner.py:105} INFO - Job 133: Subtask clean_data
[2025-03-20T11:45:51.596+0000] {task_command.py:467} INFO - Running <TaskInstance: ETL_breweries_list.clean_data manual__2025-03-20T11:43:53.685238+00:00 [running]> on host f9ccfb7c9f28
[2025-03-20T11:45:51.698+0000] {abstractoperator.py:783} ERROR - Exception rendering Jinja template for task 'clean_data', field 'application'. Template: <function fetch_and_clean_data at 0x7f87df626160>
Traceback (most recent call last):
  File "/home/airflow/.local/lib/python3.12/site-packages/airflow/models/abstractoperator.py", line 773, in _do_render_template_fields
    rendered_content = value(context=context, jinja_env=jinja_env)
                       ^^^^^^^^^^^^^^^^^^^^^^^^^^^^^^^^^^^^^^^^^^^
TypeError: fetch_and_clean_data() got an unexpected keyword argument 'context'
[2025-03-20T11:45:51.702+0000] {taskinstance.py:3313} ERROR - Task failed with exception
Traceback (most recent call last):
  File "/home/airflow/.local/lib/python3.12/site-packages/airflow/models/taskinstance.py", line 274, in _run_raw_task
    TaskInstance._execute_task_with_callbacks(
  File "/home/airflow/.local/lib/python3.12/site-packages/airflow/models/taskinstance.py", line 3117, in _execute_task_with_callbacks
    task_orig = self.render_templates(context=context, jinja_env=jinja_env)
                ^^^^^^^^^^^^^^^^^^^^^^^^^^^^^^^^^^^^^^^^^^^^^^^^^^^^^^^^^^^
  File "/home/airflow/.local/lib/python3.12/site-packages/airflow/models/taskinstance.py", line 3540, in render_templates
    original_task.render_template_fields(context, jinja_env)
  File "/home/airflow/.local/lib/python3.12/site-packages/airflow/models/baseoperator.py", line 1442, in render_template_fields
    self._do_render_template_fields(self, self.template_fields, context, jinja_env, set())
  File "/home/airflow/.local/lib/python3.12/site-packages/airflow/models/abstractoperator.py", line 773, in _do_render_template_fields
    rendered_content = value(context=context, jinja_env=jinja_env)
                       ^^^^^^^^^^^^^^^^^^^^^^^^^^^^^^^^^^^^^^^^^^^
TypeError: fetch_and_clean_data() got an unexpected keyword argument 'context'
[2025-03-20T11:45:51.724+0000] {logging_mixin.py:190} INFO - Task instance in failure state
[2025-03-20T11:45:51.725+0000] {logging_mixin.py:190} INFO - Task start:2025-03-20 11:45:51.458598+00:00 end:2025-03-20 11:45:51.723654+00:00 duration:0.265056
[2025-03-20T11:45:51.725+0000] {logging_mixin.py:190} INFO - Task:<Task(SparkSubmitOperator): clean_data> dag:<DAG: ETL_breweries_list> dagrun:<DagRun ETL_breweries_list @ 2025-03-20 11:43:53.685238+00:00: manual__2025-03-20T11:43:53.685238+00:00, state:running, queued_at: 2025-03-20 11:43:54.134280+00:00. externally triggered: True>
[2025-03-20T11:45:51.726+0000] {logging_mixin.py:190} INFO - Failure caused by fetch_and_clean_data() got an unexpected keyword argument 'context'
[2025-03-20T11:45:51.727+0000] {taskinstance.py:1226} INFO - Marking task as FAILED. dag_id=ETL_breweries_list, task_id=clean_data, run_id=manual__2025-03-20T11:43:53.685238+00:00, execution_date=20250320T114353, start_date=20250320T114551, end_date=20250320T114551
[2025-03-20T11:45:51.775+0000] {taskinstance.py:341} INFO - ::group::Post task execution logs
[2025-03-20T11:45:51.775+0000] {standard_task_runner.py:124} ERROR - Failed to execute job 133 for task clean_data (fetch_and_clean_data() got an unexpected keyword argument 'context'; 341)
Traceback (most recent call last):
  File "/home/airflow/.local/lib/python3.12/site-packages/airflow/task/task_runner/standard_task_runner.py", line 117, in _start_by_fork
    ret = args.func(args, dag=self.dag)
          ^^^^^^^^^^^^^^^^^^^^^^^^^^^^^
  File "/home/airflow/.local/lib/python3.12/site-packages/airflow/cli/cli_config.py", line 49, in command
    return func(*args, **kwargs)
           ^^^^^^^^^^^^^^^^^^^^^
  File "/home/airflow/.local/lib/python3.12/site-packages/airflow/utils/cli.py", line 116, in wrapper
    return f(*args, **kwargs)
           ^^^^^^^^^^^^^^^^^^
  File "/home/airflow/.local/lib/python3.12/site-packages/airflow/cli/commands/task_command.py", line 483, in task_run
    task_return_code = _run_task_by_selected_method(args, _dag, ti)
                       ^^^^^^^^^^^^^^^^^^^^^^^^^^^^^^^^^^^^^^^^^^^^
  File "/home/airflow/.local/lib/python3.12/site-packages/airflow/cli/commands/task_command.py", line 256, in _run_task_by_selected_method
    return _run_raw_task(args, ti)
           ^^^^^^^^^^^^^^^^^^^^^^^
  File "/home/airflow/.local/lib/python3.12/site-packages/airflow/cli/commands/task_command.py", line 341, in _run_raw_task
    return ti._run_raw_task(
           ^^^^^^^^^^^^^^^^^
  File "/home/airflow/.local/lib/python3.12/site-packages/airflow/utils/session.py", line 97, in wrapper
    return func(*args, session=session, **kwargs)
           ^^^^^^^^^^^^^^^^^^^^^^^^^^^^^^^^^^^^^^
  File "/home/airflow/.local/lib/python3.12/site-packages/airflow/models/taskinstance.py", line 3006, in _run_raw_task
    return _run_raw_task(
           ^^^^^^^^^^^^^^
  File "/home/airflow/.local/lib/python3.12/site-packages/airflow/models/taskinstance.py", line 274, in _run_raw_task
    TaskInstance._execute_task_with_callbacks(
  File "/home/airflow/.local/lib/python3.12/site-packages/airflow/models/taskinstance.py", line 3117, in _execute_task_with_callbacks
    task_orig = self.render_templates(context=context, jinja_env=jinja_env)
                ^^^^^^^^^^^^^^^^^^^^^^^^^^^^^^^^^^^^^^^^^^^^^^^^^^^^^^^^^^^
  File "/home/airflow/.local/lib/python3.12/site-packages/airflow/models/taskinstance.py", line 3540, in render_templates
    original_task.render_template_fields(context, jinja_env)
  File "/home/airflow/.local/lib/python3.12/site-packages/airflow/models/baseoperator.py", line 1442, in render_template_fields
    self._do_render_template_fields(self, self.template_fields, context, jinja_env, set())
  File "/home/airflow/.local/lib/python3.12/site-packages/airflow/models/abstractoperator.py", line 773, in _do_render_template_fields
    rendered_content = value(context=context, jinja_env=jinja_env)
                       ^^^^^^^^^^^^^^^^^^^^^^^^^^^^^^^^^^^^^^^^^^^
TypeError: fetch_and_clean_data() got an unexpected keyword argument 'context'
[2025-03-20T11:45:51.815+0000] {local_task_job_runner.py:266} INFO - Task exited with return code 1
[2025-03-20T11:45:51.854+0000] {taskinstance.py:3901} INFO - 0 downstream tasks scheduled from follow-on schedule check
[2025-03-20T11:45:51.871+0000] {local_task_job_runner.py:245} INFO - ::endgroup::
